Workbook

Sheet Bookings
B5: DATE START | E5: DATE END
B7: 46240 | E7: 46247 | H7: TOTAL: | J7: =SUMIFS(Calendar!J:J, Calendar!A:A, ">="&B7, Calendar!A:A, "<"&E7) -> 2808 | K7: $
L17: =COUNTIFS(Calendar!A:A, ">="&B7, Calendar!A:A, "<"&E7) -> 7

Sheet Control Panel
A1: Base Price | B1: 300
A3: Season Mult:
B4: Winter | C4: 1.25
B5: Low | C5: 0.85
B6: Spring | C6: 0.9
B7: Summer | C7: 1.3
B8: Fall | C8: 1.15
A10: Jour De la Semaine:
B11: Monday | C11: 0.95
B12: Tuesday | C12: 0.95
B13: Wednesday | C13: 0.95
B14: Thursday | C14: 0.95
B15: Friday | C15: 1.1
B16: Saturday | C16: 1.25
B17: Sunday | C17: 1.05
A19: Fériér
B20: New Year | C20: 0.5
B21: St-Jean | C21: 0.35
B22: Canada Day | C22: 0.35
B23: Construction Holiday | C23: 0.45
B24: Labor Day | C24: 0.25
B25: Thanksgiving | C25: 0.25
B26: Christmas | C26: 0.6

Sheet Calendar
A1: Date | B1: Day | C1: Season | D1: Season Mult | E1: Jour de la semaine | F1: Fériér | G1: Fériér Boost | H1: Adj de demande | I1: Final % | J1: Price ($)
A2: January
A3: 46023 | B3: Thursday | C3: Winter | D3: =_xlfn.XLOOKUP(C3, 'Control Panel'!$B$4:$B$8,'Control Panel'!$C$4:$C$8,"0") -> 1.25 | E3: =_xlfn.XLOOKUP(B3, 'Control Panel'!$B$11:$B$17,'Control Panel'!$C$11:$C$17,"0") -> 0.95 | F3: New Year | G3: =_xlfn.XLOOKUP(F3, 'Control Panel'!$B$20:$B$26,'Control Panel'!$C$20:$C$26,"0") -> 0.5 | H3: 0 | I3: =(D3*E3)+G3+H3 -> 1.6875 | J3: =MAX(300,SUM('Control Panel'!$B$1*I3)) -> 506.25
A4: 46024 | B4: Friday | C4: Winter | D4: =_xlfn.XLOOKUP(C4, 'Control Panel'!$B$4:$B$8,'Control Panel'!$C$4:$C$8,"0") -> 1.25 | E4: =_xlfn.XLOOKUP(B4, 'Control Panel'!$B$11:$B$17,'Control Panel'!$C$11:$C$17,"0") -> 1.1 | G4: =_xlfn.XLOOKUP(F4, 'Control Panel'!$B$20:$B$26,'Control Panel'!$C$20:$C$26,"0") -> 0 | H4: 0 | I4: =(D4*E4)+G4+H4 -> 1.375 | J4: =MAX(300,SUM('Control Panel'!$B$1*I4)) -> 412.5
A5: 46025 | B5: Saturday | C5: Winter | D5: =_xlfn.XLOOKUP(C5, 'Control Panel'!$B$4:$B$8,'Control Panel'!$C$4:$C$8,"0") -> 1.25 | E5: =_xlfn.XLOOKUP(B5, 'Control Panel'!$B$11:$B$17,'Control Panel'!$C$11:$C$17,"0") -> 1.25 | G5: =_xlfn.XLOOKUP(F5, 'Control Panel'!$B$20:$B$26,'Control Panel'!$C$20:$C$26,"0") -> 0 | H5: 0 | I5: =(D5*E5)+G5+H5 -> 1.5625 | J5: =MAX(300,SUM('Control Panel'!$B$1*I5)) -> 468.75
A6: 46026 | B6: Sunday | C6: Winter | D6: =_xlfn.XLOOKUP(C6, 'Control Panel'!$B$4:$B$8,'Control Panel'!$C$4:$C$8,"0") -> 1.25 | E6: =_xlfn.XLOOKUP(B6, 'Control Panel'!$B$11:$B$17,'Control Panel'!$C$11:$C$17,"0") -> 1.05 | G6: =_xlfn.XLOOKUP(F6, 'Control Panel'!$B$20:$B$26,'Control Panel'!$C$20:$C$26,"0") -> 0 | H6: 0 | I6: =(D6*E6)+G6+H6 -> 1.3125 | J6: =MAX(300,SUM('Control Panel'!$B$1*I6)) -> 393.75
A7: 46027 | B7: Monday | C7: Winter | D7: =_xlfn.XLOOKUP(C7, 'Control Panel'!$B$4:$B$8,'Control Panel'!$C$4:$C$8,"0") -> 1.25 | E7: =_xlfn.XLOOKUP(B7, 'Control Panel'!$B$11:$B$17,'Control Panel'!$C$11:$C$17,"0") -> 0.95 | G7: =_xlfn.XLOOKUP(F7, 'Control Panel'!$B$20:$B$26,'Control Panel'!$C$20:$C$26,"0") -> 0 | H7: 0 | I7: =(D7*E7)+G7+H7 -> 1.1875 | J7: =MAX(300,SUM('Control Panel'!$B$1*I7)) -> 356.25
A8: 46028 | B8: Tuesday | C8: Winter | D8: =_xlfn.XLOOKUP(C8, 'Control Panel'!$B$4:$B$8,'Control Panel'!$C$4:$C$8,"0") -> 1.25 | E8: =_xlfn.XLOOKUP(B8, 'Control Panel'!$B$11:$B$17,'Control Panel'!$C$11:$C$17,"0") -> 0.95 | G8: =_xlfn.XLOOKUP(F8, 'Control Panel'!$B$20:$B$26,'Control Panel'!$C$20:$C$26,"0") -> 0 | H8: 0 | I8: =(D8*E8)+G8+H8 -> 1.1875 | J8: =MAX(300,SUM('Control Panel'!$B$1*I8)) -> 356.25
A9: 46029 | B9: Wednesday | C9: Winter | D9: =_xlfn.XLOOKUP(C9, 'Control Panel'!$B$4:$B$8,'Control Panel'!$C$4:$C$8,"0") -> 1.25 | E9: =_xlfn.XLOOKUP(B9, 'Control Panel'!$B$11:$B$17,'Control Panel'!$C$11:$C$17,"0") -> 0.95 | G9: =_xlfn.XLOOKUP(F9, 'Control Panel'!$B$20:$B$26,'Control Panel'!$C$20:$C$26,"0") -> 0 | H9: 0 | I9: =(D9*E9)+G9+H9 -> 1.1875 | J9: =MAX(300,SUM('Control Panel'!$B$1*I9)) -> 356.25
A10: 46030 | B10: Thursday | C10: Winter | D10: =_xlfn.XLOOKUP(C10, 'Control Panel'!$B$4:$B$8,'Control Panel'!$C$4:$C$8,"0") -> 1.25 | E10: =_xlfn.XLOOKUP(B10, 'Control Panel'!$B$11:$B$17,'Control Panel'!$C$11:$C$17,"0") -> 0.95 | G10: =_xlfn.XLOOKUP(F10, 'Control Panel'!$B$20:$B$26,'Control Panel'!$C$20:$C$26,"0") -> 0 | H10: 0 | I10: =(D10*E10)+G10+H10 -> 1.1875 | J10: =MAX(300,SUM('Control Panel'!$B$1*I10)) -> 356.25
A11: 46031 | B11: Friday | C11: Winter | D11: =_xlfn.XLOOKUP(C11, 'Control Panel'!$B$4:$B$8,'Control Panel'!$C$4:$C$8,"0") -> 1.25 | E11: =_xlfn.XLOOKUP(B11, 'Control Panel'!$B$11:$B$17,'Control Panel'!$C$11:$C$17,"0") -> 1.1 | G11: =_xlfn.XLOOKUP(F11, 'Control Panel'!$B$20:$B$26,'Control Panel'!$C$20:$C$26,"0") -> 0 | H11: 0 | I11: =(D11*E11)+G11+H11 -> 1.375 | J11: =MAX(300,SUM('Control Panel'!$B$1*I11)) -> 412.5
A12: 46032 | B12: Saturday | C12: Winter | D12: =_xlfn.XLOOKUP(C12, 'Control Panel'!$B$4:$B$8,'Control Panel'!$C$4:$C$8,"0") -> 1.25 | E12: =_xlfn.XLOOKUP(B12, 'Control Panel'!$B$11:$B$17,'Control Panel'!$C$11:$C$17,"0") -> 1.25 | G12: =_xlfn.XLOOKUP(F12, 'Control Panel'!$B$20:$B$26,'Control Panel'!$C$20:$C$26,"0") -> 0 | H12: 0 | I12: =(D12*E12)+G12+H12 -> 1.5625 | J12: =MAX(300,SUM('Control Panel'!$B$1*I12)) -> 468.75
A13: 46033 | B13: Sunday | C13: Winter | D13: =_xlfn.XLOOKUP(C13, 'Control Panel'!$B$4:$B$8,'Control Panel'!$C$4:$C$8,"0") -> 1.25 | E13: =_xlfn.XLOOKUP(B13, 'Control Panel'!$B$11:$B$17,'Control Panel'!$C$11:$C$17,"0") -> 1.05 | G13: =_xlfn.XLOOKUP(F13, 'Control Panel'!$B$20:$B$26,'Control Panel'!$C$20:$C$26,"0") -> 0 | H13: 0 | I13: =(D13*E13)+G13+H13 -> 1.3125 | J13: =MAX(300,SUM('Control Panel'!$B$1*I13)) -> 393.75
A14: 46034 | B14: Monday | C14: Winter | D14: =_xlfn.XLOOKUP(C14, 'Control Panel'!$B$4:$B$8,'Control Panel'!$C$4:$C$8,"0") -> 1.25 | E14: =_xlfn.XLOOKUP(B14, 'Control Panel'!$B$11:$B$17,'Control Panel'!$C$11:$C$17,"0") -> 0.95 | G14: =_xlfn.XLOOKUP(F14, 'Control Panel'!$B$20:$B$26,'Control Panel'!$C$20:$C$26,"0") -> 0 | H14: 0 | I14: =(D14*E14)+G14+H14 -> 1.1875 | J14: =MAX(300,SUM('Control Panel'!$B$1*I14)) -> 356.25
A15: 46035 | B15: Tuesday | C15: Winter | D15: =_xlfn.XLOOKUP(C15, 'Control Panel'!$B$4:$B$8,'Control Panel'!$C$4:$C$8,"0") -> 1.25 | E15: =_xlfn.XLOOKUP(B15, 'Control Panel'!$B$11:$B$17,'Control Panel'!$C$11:$C$17,"0") -> 0.95 | G15: =_xlfn.XLOOKUP(F15, 'Control Panel'!$B$20:$B$26,'Control Panel'!$C$20:$C$26,"0") -> 0 | H15: 0 | I15: =(D15*E15)+G15+H15 -> 1.1875 | J15: =MAX(300,SUM('Control Panel'!$B$1*I15)) -> 356.25
... A33: 46053 | B33: Saturday | C33: Winter | D33: =_xlfn.XLOOKUP(C33, 'Control Panel'!$B$4:$B$8,'Control Panel'!$C$4:$C$8,"0") -> 1.25 | E33: =_xlfn.XLOOKUP(B33, 'Control Panel'!$B$11:$B$17,'Control Panel'!$C$11:$C$17,"0") -> 1.25 | G33: =_xlfn.XLOOKUP(F33, 'Control Panel'!$B$20:$B$26,'Control Panel'!$C$20:$C$26,"0") -> 0 | H33: 0 | I33: =(D33*E33)+G33+H33 -> 1.5625 | J33: =MAX(300,SUM('Control Panel'!$B$1*I33)) -> 468.75
A34: Feburary | G34: =_xlfn.XLOOKUP(F34, 'Control Panel'!$B$20:$B$26,'Control Panel'!$C$20:$C$26,"0") -> 0
A35: 46054 | B35: Sunday | C35: Winter | D35: =_xlfn.XLOOKUP(C35, 'Control Panel'!$B$4:$B$8,'Control Panel'!$C$4:$C$8,"0") -> 1.25 | E35: =_xlfn.XLOOKUP(B35, 'Control Panel'!$B$11:$B$17,'Control Panel'!$C$11:$C$17,"0") -> 1.05 | G35: =_xlfn.XLOOKUP(F35, 'Control Panel'!$B$20:$B$26,'Control Panel'!$C$20:$C$26,"0") -> 0 | H35: 0 | I35: =(D35*E35)+G35+H35 -> 1.3125 | J35: =MAX(300,SUM('Control Panel'!$B$1*I35)) -> 393.75
A36: 46055 | B36: Monday | C36: Winter | D36: =_xlfn.XLOOKUP(C36, 'Control Panel'!$B$4:$B$8,'Control Panel'!$C$4:$C$8,"0") -> 1.25 | E36: =_xlfn.XLOOKUP(B36, 'Control Panel'!$B$11:$B$17,'Control Panel'!$C$11:$C$17,"0") -> 0.95 | G36: =_xlfn.XLOOKUP(F36, 'Control Panel'!$B$20:$B$26,'Control Panel'!$C$20:$C$26,"0") -> 0 | H36: 0 | I36: =(D36*E36)+G36+H36 -> 1.1875 | J36: =MAX(300,SUM('Control Panel'!$B$1*I36)) -> 356.25
A37: 46056 | B37: Tuesday | C37: Winter | D37: =_xlfn.XLOOKUP(C37, 'Control Panel'!$B$4:$B$8,'Control Panel'!$C$4:$C$8,"0") -> 1.25 | E37: =_xlfn.XLOOKUP(B37, 'Control Panel'!$B$11:$B$17,'Control Panel'!$C$11:$C$17,"0") -> 0.95 | G37: =_xlfn.XLOOKUP(F37, 'Control Panel'!$B$20:$B$26,'Control Panel'!$C$20:$C$26,"0") -> 0 | H37: 0 | I37: =(D37*E37)+G37+H37 -> 1.1875 | J37: =MAX(300,SUM('Control Panel'!$B$1*I37)) -> 356.25
A38: 46057 | B38: Wednesday | C38: Winter | D38: =_xlfn.XLOOKUP(C38, 'Control Panel'!$B$4:$B$8,'Control Panel'!$C$4:$C$8,"0") -> 1.25 | E38: =_xlfn.XLOOKUP(B38, 'Control Panel'!$B$11:$B$17,'Control Panel'!$C$11:$C$17,"0") -> 0.95 | G38: =_xlfn.XLOOKUP(F38, 'Control Panel'!$B$20:$B$26,'Control Panel'!$C$20:$C$26,"0") -> 0 | H38: 0 | I38: =(D38*E38)+G38+H38 -> 1.1875 | J38: =MAX(300,SUM('Control Panel'!$B$1*I38)) -> 356.25
A39: 46058 | B39: Thursday | C39: Winter | D39: =_xlfn.XLOOKUP(C39, 'Control Panel'!$B$4:$B$8,'Control Panel'!$C$4:$C$8,"0") -> 1.25 | E39: =_xlfn.XLOOKUP(B39, 'Control Panel'!$B$11:$B$17,'Control Panel'!$C$11:$C$17,"0") -> 0.95 | G39: =_xlfn.XLOOKUP(F39, 'Control Panel'!$B$20:$B$26,'Control Panel'!$C$20:$C$26,"0") -> 0 | H39: 0 | I39: =(D39*E39)+G39+H39 -> 1.1875 | J39: =MAX(300,SUM('Control Panel'!$B$1*I39)) -> 356.25
A40: 46059 | B40: Friday | C40: Winter | D40: =_xlfn.XLOOKUP(C40, 'Control Panel'!$B$4:$B$8,'Control Panel'!$C$4:$C$8,"0") -> 1.25 | E40: =_xlfn.XLOOKUP(B40, 'Control Panel'!$B$11:$B$17,'Control Panel'!$C$11:$C$17,"0") -> 1.1 | G40: =_xlfn.XLOOKUP(F40, 'Control Panel'!$B$20:$B$26,'Control Panel'!$C$20:$C$26,"0") -> 0 | H40: 0 | I40: =(D40*E40)+G40+H40 -> 1.375 | J40: =MAX(300,SUM('Control Panel'!$B$1*I40)) -> 412.5
A41: 46060 | B41: Saturday | C41: Winter | D41: =_xlfn.XLOOKUP(C41, 'Control Panel'!$B$4:$B$8,'Control Panel'!$C$4:$C$8,"0") -> 1.25 | E41: =_xlfn.XLOOKUP(B41, 'Control Panel'!$B$11:$B$17,'Control Panel'!$C$11:$C$17,"0") -> 1.25 | G41: =_xlfn.XLOOKUP(F41, 'Control Panel'!$B$20:$B$26,'Control Panel'!$C$20:$C$26,"0") -> 0 | H41: 0 | I41: =(D41*E41)+G41+H41 -> 1.5625 | J41: =MAX(300,SUM('Control Panel'!$B$1*I41)) -> 468.75
A42: 46061 | B42: Sunday | C42: Winter | D42: =_xlfn.XLOOKUP(C42, 'Control Panel'!$B$4:$B$8,'Control Panel'!$C$4:$C$8,"0") -> 1.25 | E42: =_xlfn.XLOOKUP(B42, 'Control Panel'!$B$11:$B$17,'Control Panel'!$C$11:$C$17,"0") -> 1.05 | G42: =_xlfn.XLOOKUP(F42, 'Control Panel'!$B$20:$B$26,'Control Panel'!$C$20:$C$26,"0") -> 0 | H42: 0 | I42: =(D42*E42)+G42+H42 -> 1.3125 | J42: =MAX(300,SUM('Control Panel'!$B$1*I42)) -> 393.75
A43: 46062 | B43: Monday | C43: Winter | D43: =_xlfn.XLOOKUP(C43, 'Control Panel'!$B$4:$B$8,'Control Panel'!$C$4:$C$8,"0") -> 1.25 | E43: =_xlfn.XLOOKUP(B43, 'Control Panel'!$B$11:$B$17,'Control Panel'!$C$11:$C$17,"0") -> 0.95 | G43: =_xlfn.XLOOKUP(F43, 'Control Panel'!$B$20:$B$26,'Control Panel'!$C$20:$C$26,"0") -> 0 | H43: 0 | I43: =(D43*E43)+G43+H43 -> 1.1875 | J43: =MAX(300,SUM('Control Panel'!$B$1*I43)) -> 356.25
A44: 46063 | B44: Tuesday | C44: Winter | D44: =_xlfn.XLOOKUP(C44, 'Control Panel'!$B$4:$B$8,'Control Panel'!$C$4:$C$8,"0") -> 1.25 | E44: =_xlfn.XLOOKUP(B44, 'Control Panel'!$B$11:$B$17,'Control Panel'!$C$11:$C$17,"0") -> 0.95 | G44: =_xlfn.XLOOKUP(F44, 'Control Panel'!$B$20:$B$26,'Control Panel'!$C$20:$C$26,"0") -> 0 | H44: 0 | I44: =(D44*E44)+G44+H44 -> 1.1875 | J44: =MAX(300,SUM('Control Panel'!$B$1*I44)) -> 356.25
A45: 46064 | B45: Wednesday | C45: Winter | D45: =_xlfn.XLOOKUP(C45, 'Control Panel'!$B$4:$B$8,'Control Panel'!$C$4:$C$8,"0") -> 1.25 | E45: =_xlfn.XLOOKUP(B45, 'Control Panel'!$B$11:$B$17,'Control Panel'!$C$11:$C$17,"0") -> 0.95 | G45: =_xlfn.XLOOKUP(F45, 'Control Panel'!$B$20:$B$26,'Control Panel'!$C$20:$C$26,"0") -> 0 | H45: 0 | I45: =(D45*E45)+G45+H45 -> 1.1875 | J45: =MAX(300,SUM('Control Panel'!$B$1*I45)) -> 356.25
A46: 46065 | B46: Thursday | C46: Winter | D46: =_xlfn.XLOOKUP(C46, 'Control Panel'!$B$4:$B$8,'Control Panel'!$C$4:$C$8,"0") -> 1.25 | E46: =_xlfn.XLOOKUP(B46, 'Control Panel'!$B$11:$B$17,'Control Panel'!$C$11:$C$17,"0") -> 0.95 | G46: =_xlfn.XLOOKUP(F46, 'Control Panel'!$B$20:$B$26,'Control Panel'!$C$20:$C$26,"0") -> 0 | H46: 0 | I46: =(D46*E46)+G46+H46 -> 1.1875 | J46: =MAX(300,SUM('Control Panel'!$B$1*I46)) -> 356.25
... A62: 46081 | B62: Saturday | C62: Winter | D62: =_xlfn.XLOOKUP(C62, 'Control Panel'!$B$4:$B$8,'Control Panel'!$C$4:$C$8,"0") -> 1.25 | E62: =_xlfn.XLOOKUP(B62, 'Control Panel'!$B$11:$B$17,'Control Panel'!$C$11:$C$17,"0") -> 1.25 | G62: =_xlfn.XLOOKUP(F62, 'Control Panel'!$B$20:$B$26,'Control Panel'!$C$20:$C$26,"0") -> 0 | H62: 0 | I62: =(D62*E62)+G62+H62 -> 1.5625 | J62: =MAX(300,SUM('Control Panel'!$B$1*I62)) -> 468.75
A63: March | G63: =_xlfn.XLOOKUP(F63, 'Control Panel'!$B$20:$B$26,'Control Panel'!$C$20:$C$26,"0") -> 0
A64: 46082 | B64: Sunday | C64: Winter | D64: =_xlfn.XLOOKUP(C64, 'Control Panel'!$B$4:$B$8,'Control Panel'!$C$4:$C$8,"0") -> 1.25 | E64: =_xlfn.XLOOKUP(B64, 'Control Panel'!$B$11:$B$17,'Control Panel'!$C$11:$C$17,"0") -> 1.05 | G64: =_xlfn.XLOOKUP(F64, 'Control Panel'!$B$20:$B$26,'Control Panel'!$C$20:$C$26,"0") -> 0 | H64: 0 | I64: =(D64*E64)+G64+H64 -> 1.3125 | J64: =MAX(300,SUM('Control Panel'!$B$1*I64)) -> 393.75
A65: 46083 | B65: Monday | C65: Winter | D65: =_xlfn.XLOOKUP(C65, 'Control Panel'!$B$4:$B$8,'Control Panel'!$C$4:$C$8,"0") -> 1.25 | E65: =_xlfn.XLOOKUP(B65, 'Control Panel'!$B$11:$B$17,'Control Panel'!$C$11:$C$17,"0") -> 0.95 | G65: =_xlfn.XLOOKUP(F65, 'Control Panel'!$B$20:$B$26,'Control Panel'!$C$20:$C$26,"0") -> 0 | H65: 0 | I65: =(D65*E65)+G65+H65 -> 1.1875 | J65: =MAX(300,SUM('Control Panel'!$B$1*I65)) -> 356.25
A66: 46084 | B66: Tuesday | C66: Winter | D66: =_xlfn.XLOOKUP(C66, 'Control Panel'!$B$4:$B$8,'Control Panel'!$C$4:$C$8,"0") -> 1.25 | E66: =_xlfn.XLOOKUP(B66, 'Control Panel'!$B$11:$B$17,'Control Panel'!$C$11:$C$17,"0") -> 0.95 | G66: =_xlfn.XLOOKUP(F66, 'Control Panel'!$B$20:$B$26,'Control Panel'!$C$20:$C$26,"0") -> 0 | H66: 0 | I66: =(D66*E66)+G66+H66 -> 1.1875 | J66: =MAX(300,SUM('Control Panel'!$B$1*I66)) -> 356.25
A67: 46085 | B67: Wednesday | C67: Winter | D67: =_xlfn.XLOOKUP(C67, 'Control Panel'!$B$4:$B$8,'Control Panel'!$C$4:$C$8,"0") -> 1.25 | E67: =_xlfn.XLOOKUP(B67, 'Control Panel'!$B$11:$B$17,'Control Panel'!$C$11:$C$17,"0") -> 0.95 | G67: =_xlfn.XLOOKUP(F67, 'Control Panel'!$B$20:$B$26,'Control Panel'!$C$20:$C$26,"0") -> 0 | H67: 0 | I67: =(D67*E67)+G67+H67 -> 1.1875 | J67: =MAX(300,SUM('Control Panel'!$B$1*I67)) -> 356.25
A68: 46086 | B68: Thursday | C68: Winter | D68: =_xlfn.XLOOKUP(C68, 'Control Panel'!$B$4:$B$8,'Control Panel'!$C$4:$C$8,"0") -> 1.25 | E68: =_xlfn.XLOOKUP(B68, 'Control Panel'!$B$11:$B$17,'Control Panel'!$C$11:$C$17,"0") -> 0.95 | G68: =_xlfn.XLOOKUP(F68, 'Control Panel'!$B$20:$B$26,'Control Panel'!$C$20:$C$26,"0") -> 0 | H68: 0 | I68: =(D68*E68)+G68+H68 -> 1.1875 | J68: =MAX(300,SUM('Control Panel'!$B$1*I68)) -> 356.25
A69: 46087 | B69: Friday | C69: Winter | D69: =_xlfn.XLOOKUP(C69, 'Control Panel'!$B$4:$B$8,'Control Panel'!$C$4:$C$8,"0") -> 1.25 | E69: =_xlfn.XLOOKUP(B69, 'Control Panel'!$B$11:$B$17,'Control Panel'!$C$11:$C$17,"0") -> 1.1 | G69: =_xlfn.XLOOKUP(F69, 'Control Panel'!$B$20:$B$26,'Control Panel'!$C$20:$C$26,"0") -> 0 | H69: 0 | I69: =(D69*E69)+G69+H69 -> 1.375 | J69: =MAX(300,SUM('Control Panel'!$B$1*I69)) -> 412.5
A70: 46088 | B70: Saturday | C70: Winter | D70: =_xlfn.XLOOKUP(C70, 'Control Panel'!$B$4:$B$8,'Control Panel'!$C$4:$C$8,"0") -> 1.25 | E70: =_xlfn.XLOOKUP(B70, 'Control Panel'!$B$11:$B$17,'Control Panel'!$C$11:$C$17,"0") -> 1.25 | G70: =_xlfn.XLOOKUP(F70, 'Control Panel'!$B$20:$B$26,'Control Panel'!$C$20:$C$26,"0") -> 0 | H70: 0 | I70: =(D70*E70)+G70+H70 -> 1.5625 | J70: =MAX(300,SUM('Control Panel'!$B$1*I70)) -> 468.75
A71: 46089 | B71: Sunday | C71: Winter | D71: =_xlfn.XLOOKUP(C71, 'Control Panel'!$B$4:$B$8,'Control Panel'!$C$4:$C$8,"0") -> 1.25 | E71: =_xlfn.XLOOKUP(B71, 'Control Panel'!$B$11:$B$17,'Control Panel'!$C$11:$C$17,"0") -> 1.05 | G71: =_xlfn.XLOOKUP(F71, 'Control Panel'!$B$20:$B$26,'Control Panel'!$C$20:$C$26,"0") -> 0 | H71: 0 | I71: =(D71*E71)+G71+H71 -> 1.3125 | J71: =MAX(300,SUM('Control Panel'!$B$1*I71)) -> 393.75
A72: 46090 | B72: Monday | C72: Winter | D72: =_xlfn.XLOOKUP(C72, 'Control Panel'!$B$4:$B$8,'Control Panel'!$C$4:$C$8,"0") -> 1.25 | E72: =_xlfn.XLOOKUP(B72, 'Control Panel'!$B$11:$B$17,'Control Panel'!$C$11:$C$17,"0") -> 0.95 | G72: =_xlfn.XLOOKUP(F72, 'Control Panel'!$B$20:$B$26,'Control Panel'!$C$20:$C$26,"0") -> 0 | H72: 0 | I72: =(D72*E72)+G72+H72 -> 1.1875 | J72: =MAX(300,SUM('Control Panel'!$B$1*I72)) -> 356.25
...
